---
source: crates/ruff_linter/src/rules/flake8_debugger/mod.rs
---
error[T100]: 1:1: Trace found: `breakpoint` used

 --> T100.py:1:1
  |
1 | breakpoint()
  | ^^^^^^^^^^^^
2 | 
3 | import pdb
  |
error[T100]: 3:1: Import for `pdb` found

 --> T100.py:2:1
  |
1 | breakpoint()
2 | 
3 | import pdb
  | ^^^^^^^^^^
4 | import builtins
5 | from builtins import breakpoint
  |
error[T100]: 5:1: Import for `builtins.breakpoint` found

 --> T100.py:4:16
  |
3 | import pdb
4 | import builtins
5 | from builtins import breakpoint
  | ^^^^^^^^^^^^^^^^^^^^^^^^^^^^^^^
6 | from pdb import set_trace as st
7 | from celery.contrib.rdb import set_trace
  |
error[T100]: 6:1: Import for `pdb.set_trace` found

 --> T100.py:5:32
  |
4 | import builtins
5 | from builtins import breakpoint
6 | from pdb import set_trace as st
  | ^^^^^^^^^^^^^^^^^^^^^^^^^^^^^^^
7 | from celery.contrib.rdb import set_trace
8 | from celery.contrib import rdb
  |
error[T100]: 7:1: Import for `celery.contrib.rdb.set_trace` found

 --> T100.py:6:32
  |
5 | from builtins import breakpoint
6 | from pdb import set_trace as st
7 | from celery.contrib.rdb import set_trace
  | ^^^^^^^^^^^^^^^^^^^^^^^^^^^^^^^^^^^^^^^^
8 | from celery.contrib import rdb
9 | import celery.contrib.rdb
  |
error[T100]: 9:1: Import for `celery.contrib.rdb` found

  --> T100.py:8:31
   |
 7 | from celery.contrib.rdb import set_trace
 8 | from celery.contrib import rdb
 9 | import celery.contrib.rdb
   | ^^^^^^^^^^^^^^^^^^^^^^^^^
10 | from debugpy import wait_for_client
11 | import debugpy
   |
error[T100]: 10:1: Import for `debugpy.wait_for_client` found

  --> T100.py:9:26
   |
 8 | from celery.contrib import rdb
 9 | import celery.contrib.rdb
10 | from debugpy import wait_for_client
   | ^^^^^^^^^^^^^^^^^^^^^^^^^^^^^^^^^^^
11 | import debugpy
12 | from ptvsd import break_into_debugger
   |
error[T100]: 11:1: Import for `debugpy` found

  --> T100.py:10:36
   |
 9 | import celery.contrib.rdb
10 | from debugpy import wait_for_client
11 | import debugpy
   | ^^^^^^^^^^^^^^
12 | from ptvsd import break_into_debugger
13 | from ptvsd import enable_attach
   |
error[T100]: 12:1: Import for `ptvsd.break_into_debugger` found

  --> T100.py:11:15
   |
10 | from debugpy import wait_for_client
11 | import debugpy
12 | from ptvsd import break_into_debugger
   | ^^^^^^^^^^^^^^^^^^^^^^^^^^^^^^^^^^^^^
13 | from ptvsd import enable_attach
14 | from ptvsd import wait_for_attach
   |
error[T100]: 14:1: Import for `ptvsd.wait_for_attach` found

  --> T100.py:13:32
   |
12 | from ptvsd import break_into_debugger
13 | from ptvsd import enable_attach
14 | from ptvsd import wait_for_attach
   | ^^^^^^^^^^^^^^^^^^^^^^^^^^^^^^^^^
15 | import ptvsd
   |
error[T100]: 15:1: Import for `ptvsd` found

  --> T100.py:14:34
   |
13 | from ptvsd import enable_attach
14 | from ptvsd import wait_for_attach
15 | import ptvsd
   | ^^^^^^^^^^^^
16 | 
17 | breakpoint()
   |
error[T100]: 17:1: Trace found: `builtins.breakpoint` used

  --> T100.py:16:1
   |
15 | import ptvsd
16 | 
17 | breakpoint()
   | ^^^^^^^^^^^^
18 | st()
19 | set_trace()
   |
error[T100]: 18:1: Trace found: `pdb.set_trace` used

  --> T100.py:17:13
   |
17 | breakpoint()
18 | st()
   | ^^^^
19 | set_trace()
20 | debugpy.breakpoint()
   |
error[T100]: 19:1: Trace found: `celery.contrib.rdb.set_trace` used

  --> T100.py:18:5
   |
17 | breakpoint()
18 | st()
19 | set_trace()
   | ^^^^^^^^^^^
20 | debugpy.breakpoint()
21 | wait_for_client()
   |
error[T100]: 20:1: Trace found: `debugpy.breakpoint` used

  --> T100.py:19:12
   |
18 | st()
19 | set_trace()
20 | debugpy.breakpoint()
   | ^^^^^^^^^^^^^^^^^^^^
21 | wait_for_client()
22 | debugpy.listen(1234)
   |
error[T100]: 21:1: Trace found: `debugpy.wait_for_client` used

  --> T100.py:20:21
   |
19 | set_trace()
20 | debugpy.breakpoint()
21 | wait_for_client()
   | ^^^^^^^^^^^^^^^^^
22 | debugpy.listen(1234)
23 | enable_attach()
   |
error[T100]: 22:1: Trace found: `debugpy.listen` used

  --> T100.py:21:18
   |
20 | debugpy.breakpoint()
21 | wait_for_client()
22 | debugpy.listen(1234)
   | ^^^^^^^^^^^^^^^^^^^^
23 | enable_attach()
24 | break_into_debugger()
   |
error[T100]: 24:1: Trace found: `ptvsd.break_into_debugger` used

  --> T100.py:23:16
   |
22 | debugpy.listen(1234)
23 | enable_attach()
24 | break_into_debugger()
   | ^^^^^^^^^^^^^^^^^^^^^
25 | wait_for_attach()
   |
error[T100]: 25:1: Trace found: `ptvsd.wait_for_attach` used

  --> T100.py:24:22
   |
23 | enable_attach()
24 | break_into_debugger()
25 | wait_for_attach()
   | ^^^^^^^^^^^^^^^^^
   |
